<?xml version="1.0" encoding="utf-8" ?>
<!-- =================================================================================== -->
<!-- |    This document was autogenerated by xacro from /home/pickle/hpro_ws/src/workstation/agv_vehicle/urdf/agv_arm.urdf.xacro | -->
<!-- |    EDITING THIS FILE BY HAND IS NOT RECOMMENDED                                 | -->
<!-- =================================================================================== -->
<robot name="agv_arm">
    <!-- Init colour -->
    <!-- rgba: red green blue alpha -->
    <!-- RGBA Table: https://tool.oschina.net/commons?type=3 -->
    <material name="black">
        <color rgba="0.0 0.0 0.0 1.0" />
    </material>
    <material name="dark">
        <color rgba="0.3 0.3 0.3 1.0" />
    </material>
    <material name="light_black">
        <color rgba="0.4 0.4 0.4 1.0" />
    </material>
    <material name="blue">
        <color rgba="0.0 0.0 0.8 1.0" />
    </material>
    <material name="green">
        <color rgba="0.0 0.8 0.0 1.0" />
    </material>
    <material name="grey">
        <color rgba="0.5 0.5 0.5 1.0" />
    </material>
    <material name="orange">
        <color rgba="1.0 0.423529411765 0.0392156862745 1.0" />
    </material>
    <material name="brown">
        <color rgba="0.870588235294 0.811764705882 0.764705882353 1.0" />
    </material>
    <material name="red">
        <color rgba="0.8 0.0 0.0 1.0" />
    </material>
    <material name="white">
        <color rgba="1.0 1.0 1.0 1.0" />
    </material>
    <material name="pink">
        <color rgba="1.0 0.411764705882 0.705882352941 1.0" />
    </material>
    <material name="DeepSkyBlue2">
        <color rgba="0 0.698039215686 0.933333333333 1.0" />
    </material>
    <material name="MediumOrchid1">
        <color rgba="0.878431372549 0.4 1 1.0" />
    </material>
    <gazebo reference="base_link">
        <material>Gazebo/DarkGrey</material>
    </gazebo>
    <!-- Set the reference value is base_link and material set Gazebo/FlatBlack -->
    <!-- Set the friction coefficients is mu1 and mu2 -->
    <!-- Set the contant stiffness kp and damping kd -->
    <!-- Set the minimum allowable depth before contact correction impulse is applied -->
    <!-- Set the maximum contact correction velocity truncation term -->
    <!-- Set the friction mu1 direction in the collision local reference -->
    <gazebo reference="agv_leftwheel">
        <mu1>10000</mu1>
        <mu2>10000</mu2>
        <kp>500000.0</kp>
        <kd>100.0</kd>
        <minDepth>0.001</minDepth>
        <maxVel>1.0</maxVel>
        <fdir1>1 0 0</fdir1>
        <material>Gazebo/FlatBlack</material>
    </gazebo>
    <gazebo reference="agv_rightwheel">
        <mu1>10000</mu1>
        <mu2>10000</mu2>
        <kp>500000.0</kp>
        <kd>100.0</kd>
        <minDepth>0.001</minDepth>
        <maxVel>1.0</maxVel>
        <fdir1>1 0 0</fdir1>
        <material>Gazebo/FlatBlack</material>
    </gazebo>
    <gazebo reference="agv_casterwheel_11">
        <mu1>0.01</mu1>
        <mu2>0.01</mu2>
        <kp>1000000.0</kp>
        <kd>100.0</kd>
        <minDepth>0.001</minDepth>
        <maxVel>0.1</maxVel>
        <fdir1>0 0 1</fdir1>
        <material>Gazebo/FlatBlack</material>
    </gazebo>
    <gazebo reference="agv_casterwheel_12">
        <mu1>0.01</mu1>
        <mu2>0.01</mu2>
        <kp>1000000.0</kp>
        <kd>100.0</kd>
        <minDepth>0.001</minDepth>
        <maxVel>0.1</maxVel>
        <fdir1>0 -1 0</fdir1>
        <material>Gazebo/FlatBlack</material>
    </gazebo>
    <gazebo reference="agv_casterwheel_21">
        <mu1>0.01</mu1>
        <mu2>0.01</mu2>
        <kp>1000000.0</kp>
        <kd>100.0</kd>
        <minDepth>0.001</minDepth>
        <maxVel>0.1</maxVel>
        <fdir1>0 0 1</fdir1>
        <material>Gazebo/FlatBlack</material>
    </gazebo>
    <gazebo reference="agv_casterwheel_22">
        <mu1>0.01</mu1>
        <mu2>0.01</mu2>
        <kp>1000000.0</kp>
        <kd>100.0</kd>
        <minDepth>0.001</minDepth>
        <maxVel>1.0</maxVel>
        <fdir1>0 -1 0</fdir1>
        <material>Gazebo/FlatBlack</material>
    </gazebo>
    <gazebo reference="agv_casterwheel_31">
        <mu1>0.01</mu1>
        <mu2>0.01</mu2>
        <kp>1000000.0</kp>
        <kd>100.0</kd>
        <minDepth>0.001</minDepth>
        <maxVel>0.1</maxVel>
        <fdir1>0 0 1</fdir1>
        <material>Gazebo/FlatBlack</material>
    </gazebo>
    <gazebo reference="agv_casterwheel_32">
        <mu1>0.01</mu1>
        <mu2>0.01</mu2>
        <kp>1000000.0</kp>
        <kd>100.0</kd>
        <minDepth>0.001</minDepth>
        <maxVel>0.1</maxVel>
        <fdir1>0 -1 0</fdir1>
        <material>Gazebo/FlatBlack</material>
    </gazebo>
    <gazebo reference="agv_casterwheel_41">
        <mu1>0.01</mu1>
        <mu2>0.01</mu2>
        <kp>1000000.0</kp>
        <kd>100.0</kd>
        <minDepth>0.001</minDepth>
        <maxVel>0.1</maxVel>
        <fdir1>0 0 1</fdir1>
        <material>Gazebo/FlatBlack</material>
    </gazebo>
    <gazebo reference="agv_casterwheel_42">
        <mu1>0.01</mu1>
        <mu2>0.01</mu2>
        <kp>1000000.0</kp>
        <kd>100.0</kd>
        <minDepth>0.001</minDepth>
        <maxVel>0.1</maxVel>
        <fdir1>0 -1 0</fdir1>
        <material>Gazebo/FlatBlack</material>
    </gazebo>
    <gazebo>
        <plugin filename="libgazebo_ros_diff_drive.so" name="agv_vehicle_controller">
            <commandTopic>cmd_vel</commandTopic>
            <odometryTopic>odom</odometryTopic>
            <odometryFrame>odom</odometryFrame>
            <robotBaseFrame>base_footprint</robotBaseFrame>
            <publishWheelTF>true</publishWheelTF>
            <publishTf>true</publishTf>
            <publishWheelJointState>true</publishWheelJointState>
            <legacyMode>false</legacyMode>
            <updateRate>30</updateRate>
            <leftJoint>agv_leftwheel_joint</leftJoint>
            <rightJoint>agv_rightwheel_joint</rightJoint>
            <wheelSeparation>0.36</wheelSeparation>
            <wheelDiameter>0.162</wheelDiameter>
            <wheelAcceleration>1</wheelAcceleration>
            <wheelTorque>10</wheelTorque>
            <rosDebugLevel>na</rosDebugLevel>
        </plugin>
    </gazebo>
    <gazebo reference="agv_laserrader">
        <material>Gazebo/FlatBlack</material>
        <sensor name="lader_sensor" type="ray">
            <pose>0 0 0 0 0 0</pose>
            <visualize>false</visualize>
            <ray>
                <scan>
                    <horizontal>
                        <samples>360</samples>
                        <resolution>1</resolution>
                        <min_angle>0.0</min_angle>
                        <max_angle>3.14</max_angle>
                    </horizontal>
                </scan>
                <range>
                    <min>0.120</min>
                    <max>3.5</max>
                    <resolution>0.015</resolution>
                </range>
                <noise>
                    <type>gaussian</type>
                    <mean>0.0</mean>
                    <stddev>0.01</stddev>
                </noise>
            </ray>
            <plugin filename="libgazebo_ros_laser.so" name="gazebo_ros_lds_lfcd_controller">
                <topicName>scan</topicName>
                <frameName>agv_laserrader</frameName>
                <update_rate>1800</update_rate>
            </plugin>
        </sensor>
    </gazebo>
    <link name="base_footprint" />
    <joint name="base_joint" type="fixed">
        <parent link="base_footprint" />
        <child link="base_link" />
        <origin rpy="0 0 0" xyz="0 0 0" />
    </joint>
    <link name="base_link">
        
<inertial>
            <origin rpy="0 0 0" xyz="-0.011337 0.0002178 0.074729" />
            <mass value="26.01" />
            <inertia ixx="0.55125" ixy="-0.00023371" ixz="-0.0035396" iyy="1.0618" iyz="-2.8551E-05" izz="1.5053" />
        </inertial>

        <visual>
            <origin rpy="0 0 0" xyz="0 0 0" />
            <geometry>
                <mesh filename="package://agv_vehicle/meshes/agv_base.STL" />
            </geometry>
            <material name="pink" />
        </visual>
        <collision>
            <origin rpy="0 0 0" xyz="0 0 0" />
            <geometry>
                <mesh filename="package://agv_vehicle/meshes/agv_base.STL" />
            </geometry>
        </collision>
    </link>
    <link name="agv_leftwheel">
        
<inertial>
            <origin rpy="0 0 0" xyz="4.7644E-07 0.031408 -1.4108E-07" />
            <mass value="0.80487" />
            <inertia ixx="0.0012651" ixy="-1.0197E-08" ixz="1.5643E-10" iyy="0.0022826" iyz="3.0196E-09" izz="0.0012651" />
        </inertial>

        <visual>
            <origin rpy="0 0 0" xyz="0 0 0" />
            <geometry>
                <mesh filename="package://agv_vehicle/meshes/agv_leftwheel.STL" />
            </geometry>
            <material name="">
                <color rgba="0.75294 0.75294 0.75294 1" />
            </material>
        </visual>
        <collision>
            <origin rpy="0 0 0" xyz="0 0 0" />
            <geometry>
                <mesh filename="package://agv_vehicle/meshes/agv_leftwheel.STL" />
            </geometry>
        </collision>
    </link>
    <joint name="agv_leftwheel_joint" type="continuous">
        <origin rpy="0 0 0" xyz="0 0.1695 -0.023" />
        <parent link="base_link" />
        <child link="agv_leftwheel" />
        <axis xyz="0 1 0" />
    </joint>
    <link name="agv_rightwheel">
        
<inertial>
            <origin rpy="0 0 0" xyz="-1.4483E-07 -0.031408 4.7531E-07" />
            <mass value="0.80487" />
            <inertia ixx="0.0012651" ixy="-3.0997E-09" ixz="1.5483E-10" iyy="0.0022826" iyz="1.0173E-08" izz="0.0012651" />
        </inertial>

        <visual>
            <origin rpy="0 0 0" xyz="0 0 0" />
            <geometry>
                <mesh filename="package://agv_vehicle/meshes/agv_rightwheel.STL" />
            </geometry>
            <material name="">
                <color rgba="0.75294 0.75294 0.75294 1" />
            </material>
        </visual>
        <collision>
            <origin rpy="0 0 0" xyz="0 0 0" />
            <geometry>
                <mesh filename="package://agv_vehicle/meshes/agv_rightwheel.STL" />
            </geometry>
        </collision>
    </link>
    <joint name="agv_rightwheel_joint" type="continuous">
        <origin rpy="0 0 0" xyz="0 -0.1695 -0.023" />
        <parent link="base_link" />
        <child link="agv_rightwheel" />
        <axis xyz="0 1 0" />
    </joint>
    <link name="agv_casterwheel_11">
        
<inertial>
            <origin rpy="0 0 0" xyz="0.015124 0.00018551 -0.027117" />
            <mass value="0.029345" />
            <inertia ixx="1.6485E-05" ixy="-6.4477E-09" ixz="3.8454E-06" iyy="1.697E-05" iyz="4.7562E-08" izz="1.6895E-05" />
        </inertial>

        <visual>
            <origin rpy="0 0 0" xyz="0 0 0" />
            <geometry>
                <mesh filename="package://agv_vehicle/meshes/agv_casterwheel_11.STL" />
            </geometry>
            <material name="">
                <color rgba="0.78039 0.76078 0.74118 1" />
            </material>
        </visual>
        <collision>
            <origin rpy="0 0 0" xyz="0 0 0" />
            <geometry>
                <mesh filename="package://agv_vehicle/meshes/agv_casterwheel_11.STL" />
            </geometry>
        </collision>
    </link>
    <joint name="agv_casterwheel_11_joint" type="continuous">
        <origin rpy="0 0 0" xyz="0.25 0.16 -0.005" />
        <parent link="base_link" />
        <child link="agv_casterwheel_11" />
        <axis xyz="0 0 1" />
    </joint>
    <link name="agv_casterwheel_12">
        
<inertial>
            <origin rpy="0 0 0" xyz="-6.1062E-16 0.017 -1.6237E-15" />
            <mass value="0.10593" />
            <inertia ixx="4.2514E-05" ixy="-3.2293E-21" ixz="3.2662E-21" iyy="7.4377E-05" iyz="-3.0247E-18" izz="4.2514E-05" />
        </inertial>

        <visual>
            <origin rpy="0 0 0" xyz="0 0 0" />
            <geometry>
                <mesh filename="package://agv_vehicle/meshes/agv_casterwheel_12.STL" />
            </geometry>
            <material name="">
                <color rgba="0.29804 0.29804 0.29804 1" />
            </material>
        </visual>
        <collision>
            <origin rpy="0 0 0" xyz="0 0 0" />
            <geometry>
                <mesh filename="package://agv_vehicle/meshes/agv_casterwheel_12.STL" />
            </geometry>
        </collision>
    </link>
    <joint name="agv_casterwheel_12_joint" type="continuous">
        <origin rpy="0 0 0.012273" xyz="0.033206 -0.016594 -0.0615" />
        <parent link="agv_casterwheel_11" />
        <child link="agv_casterwheel_12" />
        <axis xyz="0 -1 0" />
    </joint>
    <link name="agv_casterwheel_21">
        
<inertial>
            <origin rpy="0 0 0" xyz="0.015122 0.00034602 -0.027117" />
            <mass value="0.029345" />
            <inertia ixx="1.6485E-05" ixy="-1.1605E-08" ixz="3.8447E-06" iyy="1.697E-05" iyz="8.8399E-08" izz="1.6895E-05" />
        </inertial>

        <visual>
            <origin rpy="0 0 0" xyz="0 0 0" />
            <geometry>
                <mesh filename="package://agv_vehicle/meshes/agv_casterwheel_21.STL" />
            </geometry>
            <material name="">
                <color rgba="0.78039 0.76078 0.74118 1" />
            </material>
        </visual>
        <collision>
            <origin rpy="0 0 0" xyz="0 0 0" />
            <geometry>
                <mesh filename="package://agv_vehicle/meshes/agv_casterwheel_21.STL" />
            </geometry>
        </collision>
    </link>
    <joint name="agv_casterwheel_21_joint" type="continuous">
        <origin rpy="0 0 0" xyz="0.25 -0.16 -0.005" />
        <parent link="base_link" />
        <child link="agv_casterwheel_21" />
        <axis xyz="0 0 1" />
    </joint>
    <link name="agv_casterwheel_22">
        
<inertial>
            <origin rpy="0 0 0" xyz="-0.00038904 0.016996 -1.3878E-17" />
            <mass value="0.10593" />
            <inertia ixx="4.253E-05" ixy="-7.29E-07" ixz="1.2662E-21" iyy="7.436E-05" iyz="-6.4689E-21" izz="4.2514E-05" />
        </inertial>

        <visual>
            <origin rpy="0 0 0" xyz="0 0 0" />
            <geometry>
                <mesh filename="package://agv_vehicle/meshes/agv_casterwheel_22.STL" />
            </geometry>
            <material name="">
                <color rgba="0.29804 0.29804 0.29804 1" />
            </material>
        </visual>
        <collision>
            <origin rpy="0 0 0" xyz="0 0 0" />
            <geometry>
                <mesh filename="package://agv_vehicle/meshes/agv_casterwheel_22.STL" />
            </geometry>
        </collision>
    </link>
    <joint name="agv_casterwheel_22_joint" type="continuous">
        <origin rpy="0 0 0" xyz="0.03338 -0.01624 -0.0615" />
        <parent link="agv_casterwheel_21" />
        <child link="agv_casterwheel_22" />
        <axis xyz="0 -1 0" />
    </joint>
    <link name="agv_casterwheel_31">
        
<inertial>
            <origin rpy="0 0 0" xyz="0.01512 0.00041523 -0.027117" />
            <mass value="0.029345" />
            <inertia ixx="1.6485E-05" ixy="-1.3932E-08" ixz="3.8443E-06" iyy="1.697E-05" iyz="1.0596E-07" izz="1.6895E-05" />
        </inertial>

        <visual>
            <origin rpy="0 0 0" xyz="0 0 0" />
            <geometry>
                <mesh filename="package://agv_vehicle/meshes/agv_casterwheel_31.STL" />
            </geometry>
            <material name="">
                <color rgba="0.78039 0.76078 0.74118 1" />
            </material>
        </visual>
        <collision>
            <origin rpy="0 0 0" xyz="0 0 0" />
            <geometry>
                <mesh filename="package://agv_vehicle/meshes/agv_casterwheel_31.STL" />
            </geometry>
        </collision>
    </link>
    <joint name="agv_casterwheel_31_joint" type="continuous">
        <origin rpy="0 0 0" xyz="-0.25 0.16 -0.005" />
        <parent link="base_link" />
        <child link="agv_casterwheel_31" />
        <axis xyz="0 0 1" />
    </joint>
    <link name="agv_casterwheel_32">
        
<inertial>
            <origin rpy="0 0 0" xyz="-0.00046678 0.016994 1.3878E-17" />
            <mass value="0.10593" />
            <inertia ixx="4.2538E-05" ixy="-8.7457E-07" ixz="4.1031E-21" iyy="7.4353E-05" iyz="-2.7645E-21" izz="4.2514E-05" />
        </inertial>

        <visual>
            <origin rpy="0 0 0" xyz="0 0 0" />
            <geometry>
                <mesh filename="package://agv_vehicle/meshes/agv_casterwheel_32.STL" />
            </geometry>
            <material name="">
                <color rgba="0.29804 0.29804 0.29804 1" />
            </material>
        </visual>
        <collision>
            <origin rpy="0 0 0" xyz="0 0 0" />
            <geometry>
                <mesh filename="package://agv_vehicle/meshes/agv_casterwheel_32.STL" />
            </geometry>
        </collision>
    </link>
    <joint name="agv_casterwheel_32_joint" type="continuous">
        <origin rpy="0 0 0" xyz="0.033454 -0.016087 -0.0615" />
        <parent link="agv_casterwheel_31" />
        <child link="agv_casterwheel_32" />
        <axis xyz="0 -1 0" />
    </joint>
    <link name="agv_casterwheel_41">
        
<inertial>
            <origin rpy="0 0 0" xyz="0.015125 -0.00011453 -0.027117" />
            <mass value="0.029345" />
            <inertia ixx="1.6485E-05" ixy="3.1032E-09" ixz="3.8456E-06" iyy="1.697E-05" iyz="-2.8743E-08" izz="1.6895E-05" />
        </inertial>

        <visual>
            <origin rpy="0 0 0" xyz="0 0 0" />
            <geometry>
                <mesh filename="package://agv_vehicle/meshes/agv_casterwheel_41.STL" />
            </geometry>
            <material name="">
                <color rgba="0.78039 0.76078 0.74118 1" />
            </material>
        </visual>
        <collision>
            <origin rpy="0 0 0" xyz="0 0 0" />
            <geometry>
                <mesh filename="package://agv_vehicle/meshes/agv_casterwheel_41.STL" />
            </geometry>
        </collision>
    </link>
    <joint name="agv_casterwheel_41_joint" type="continuous">
        <origin rpy="0 0 0" xyz="-0.25 -0.16 -0.005" />
        <parent link="base_link" />
        <child link="agv_casterwheel_41" />
        <axis xyz="0 0 1" />
    </joint>
    <link name="agv_casterwheel_42">
        
<inertial>
            <origin rpy="0 0 0" xyz="0.00012865 0.017 0" />
            <mass value="0.10593" />
            <inertia ixx="4.2516E-05" ixy="2.4113E-07" ixz="-2.3416E-21" iyy="7.4375E-05" iyz="-8.9403E-21" izz="4.2514E-05" />
        </inertial>

        <visual>
            <origin rpy="0 0 0" xyz="0 0 0" />
            <geometry>
                <mesh filename="package://agv_vehicle/meshes/agv_casterwheel_42.STL" />
            </geometry>
            <material name="">
                <color rgba="0.29804 0.29804 0.29804 1" />
            </material>
        </visual>
        <collision>
            <origin rpy="0 0 0" xyz="0 0 0" />
            <geometry>
                <mesh filename="package://agv_vehicle/meshes/agv_casterwheel_42.STL" />
            </geometry>
        </collision>
    </link>
    <joint name="agv_casterwheel_42" type="continuous">
        <origin rpy="0 0 0" xyz="0.03287 -0.017249 -0.0615" />
        <parent link="agv_casterwheel_41" />
        <child link="agv_casterwheel_42" />
        <axis xyz="0 -1 0" />
    </joint>
    <link name="agv_laserrader">
        
<inertial>
            <origin rpy="0 0 0" xyz="-0.003337 8.6874E-07 -0.019431" />
            <mass value="0.14399" />
            <inertia ixx="6.8842E-05" ixy="-4.5304E-09" ixz="-5.5211E-06" iyy="8.5485E-05" iyz="1.7638E-09" izz="0.00011058" />
        </inertial>

        <visual>
            <origin rpy="0 0 0" xyz="0 0 0" />
            <geometry>
                <mesh filename="package://agv_vehicle/meshes/agv_laserrader.STL" />
            </geometry>
            <material name="">
                <color rgba="0.79216 0.81961 0.93333 1" />
            </material>
        </visual>
        <collision>
            <origin rpy="0 0 0" xyz="0 0 0" />
            <geometry>
                <mesh filename="package://agv_vehicle/meshes/agv_laserrader.STL" />
            </geometry>
        </collision>
    </link>
    <joint name="agv_laserrader_joint" type="fixed">
        <origin rpy="0 0 -1.5707" xyz="0.2817 0 0.066" />
        <parent link="base_link" />
        <child link="agv_laserrader" />
        <axis xyz="0 0 0" />
    </joint>
    <link name="agv_shelf">
        
<inertial>
            <origin rpy="0 0 0" xyz="0.00012261 0.00020991 -0.074781" />
            <mass value="1.35775" />
            <inertia ixx="0.0091958" ixy="7.7198E-06" ixz="3.9744E-06" iyy="0.0044251" iyz="6.1521E-06" izz="0.0087252" />
        </inertial>

        <visual>
            <origin rpy="0 0 0" xyz="0 0 0" />
            <geometry>
                <mesh filename="package://agv_vehicle/meshes/agv_shelf.STL" />
            </geometry>
            <material name="">
                <color rgba="0.79216 0.81961 0.93333 1" />
            </material>
        </visual>
        <collision>
            <origin rpy="0 0 0" xyz="0 0 0" />
            <geometry>
                <mesh filename="package://agv_vehicle/meshes/agv_shelf.STL" />
            </geometry>
        </collision>
    </link>
    <joint name="agv_shelf_joint" type="fixed">
        <origin rpy="0 0 0" xyz="0.229 -0.001 0.55" />
        <parent link="base_link" />
        <child link="agv_shelf" />
        <axis xyz="0 0 0" />
    </joint>
    <link name="agv_cobot_base">
        
<inertial>
            <origin rpy="0 0 0" xyz="0.017961 -8.9547E-06 0.062679" />
            <mass value="3.1281" />
            <inertia ixx="0.011805" ixy="3.8131E-06" ixz="0.0017999" iyy="0.01583" iyz="-8.2464E-07" izz="0.012949" />
        </inertial>

        <visual>
            <origin rpy="0 0 0" xyz="0 0 0" />
            <geometry>
                <mesh filename="package://agv_cobot/meshes/agv_cobot_base.STL" />
            </geometry>
            <material name="">
                <color rgba="0.59216 0.66667 0.68235 1" />
            </material>
        </visual>
        <collision>
            <origin rpy="0 0 0" xyz="0 0 0" />
            <geometry>
                <mesh filename="package://agv_cobot/meshes/agv_cobot_base.STL" />
            </geometry>
        </collision>
    </link>
    <link name="agv_cobot_1_link">
        
<inertial>
            <origin rpy="0 0 0" xyz="-3.3729E-06 0.025273 0.11306" />
            <mass value="1.8005" />
            <inertia ixx="0.0095698" ixy="-6.8876E-07" ixz="4.7542E-07" iyy="0.0085643" iyz="-0.0019573" izz="0.0033056" />
        </inertial>

        <visual>
            <origin rpy="0 0 0" xyz="0 0 0" />
            <geometry>
                <mesh filename="package://agv_cobot/meshes/agv_cobot_1_link.STL" />
            </geometry>
            <material name="">
                <color rgba="0.59216 0.66667 0.68235 1" />
            </material>
        </visual>
        <collision>
            <origin rpy="0 0 0" xyz="0 0 0" />
            <geometry>
                <mesh filename="package://agv_cobot/meshes/agv_cobot_1_link.STL" />
            </geometry>
        </collision>
    </link>
    <joint name="agv_cobot_1_joint" type="revolute">
        <origin rpy="0 0 0" xyz="0 0 0.175" />
        <parent link="agv_cobot_base" />
        <child link="agv_cobot_1_link" />
        <axis xyz="0 0 -1" />
        <limit effort="40" lower="-3.14" upper="3.14" velocity="5" />
    </joint>
    <link name="agv_cobot_2_link">
        
<inertial>
            <origin rpy="0 0 0" xyz="6.1113E-06 0.094688 0.012136" />
            <mass value="2.1853" />
            <inertia ixx="0.017961" ixy="2.0018E-07" ixz="-7.1727E-07" iyy="0.0044673" iyz="0.0045671" izz="0.016295" />
        </inertial>

        <visual>
            <origin rpy="0 0 0" xyz="0 0 0" />
            <geometry>
                <mesh filename="package://agv_cobot/meshes/agv_cobot_2_link.STL" />
            </geometry>
            <material name="">
                <color rgba="0.59216 0.66667 0.68235 1" />
            </material>
        </visual>
        <collision>
            <origin rpy="0 0 0" xyz="0 0 0" />
            <geometry>
                <mesh filename="package://agv_cobot/meshes/agv_cobot_2_link.STL" />
            </geometry>
        </collision>
    </link>
    <joint name="agv_cobot_2_joint" type="revolute">
        <origin rpy="1.5708 0 0" xyz="0 -0.0155 0.1665" />
        <parent link="agv_cobot_1_link" />
        <child link="agv_cobot_2_link" />
        <axis xyz="0 0 -1" />
        <limit effort="40" lower="-3.14" upper="3.14" velocity="5" />
    </joint>
    <link name="agv_cobot_3_link">
        
<inertial>
            <origin rpy="0 0 0" xyz="-1.4376E-06 0.025269 0.11105" />
            <mass value="1.8005" />
            <inertia ixx="0.0095704" ixy="-7.0638E-07" ixz="4.2065E-07" iyy="0.0085644" iyz="-0.0019581" izz="0.0033061" />
        </inertial>

        <visual>
            <origin rpy="0 0 0" xyz="0 0 0" />
            <geometry>
                <mesh filename="package://agv_cobot/meshes/agv_cobot_3_link.STL" />
            </geometry>
            <material name="">
                <color rgba="0.79216 0.81961 0.93333 1" />
            </material>
        </visual>
        <collision>
            <origin rpy="0 0 0" xyz="0 0 0" />
            <geometry>
                <mesh filename="package://agv_cobot/meshes/agv_cobot_3_link.STL" />
            </geometry>
        </collision>
    </link>
    <joint name="agv_cobot_3_joint" type="revolute">
        <origin rpy="-1.5708 0 0" xyz="0 0.2295 -0.015501" />
        <parent link="agv_cobot_2_link" />
        <child link="agv_cobot_3_link" />
        <axis xyz="0 0 -1" />
        <limit effort="40" lower="-3.14" upper="3.14" velocity="5" />
    </joint>
    <link name="agv_cobot_4_link">
        
<inertial>
            <origin rpy="0 0 0" xyz="-2.8466E-06 0.075669 0.019416" />
            <mass value="1.8001" />
            <inertia ixx="0.013099" ixy="5.1414E-07" ixz="-1.4286E-07" iyy="0.0033653" iyz="0.003477" izz="0.011753" />
        </inertial>

        <visual>
            <origin rpy="0 0 0" xyz="0 0 0" />
            <geometry>
                <mesh filename="package://agv_cobot/meshes/agv_cobot_4_link.STL" />
            </geometry>
            <material name="">
                <color rgba="0.59216 0.66667 0.68235 1" />
            </material>
        </visual>
        <collision>
            <origin rpy="0 0 0" xyz="0 0 0" />
            <geometry>
                <mesh filename="package://agv_cobot/meshes/agv_cobot_4_link.STL" />
            </geometry>
        </collision>
    </link>
    <joint name="agv_cobot_4_joint" type="revolute">
        <origin rpy="1.5708 0 0" xyz="0 -0.0135 0.1645" />
        <parent link="agv_cobot_3_link" />
        <child link="agv_cobot_4_link" />
        <axis xyz="0 0 -1" />
        <limit effort="40" lower="-3.14" upper="3.14" velocity="5" />
    </joint>
    <link name="agv_cobot_5_link">
        
<inertial>
            <origin rpy="0 0 0" xyz="-1.221E-05 0.031276 0.1025" />
            <mass value="1.2958" />
            <inertia ixx="0.0059855" ixy="-4.7385E-07" ixz="-5.4528E-07" iyy="0.0048983" iyz="-0.0015266" izz="0.0022675" />
        </inertial>

        <visual>
            <origin rpy="0 0 0" xyz="0 0 0" />
            <geometry>
                <mesh filename="package://agv_cobot/meshes/agv_cobot_5_link.STL" />
            </geometry>
            <material name="">
                <color rgba="0.59216 0.66667 0.68235 1" />
            </material>
        </visual>
        <collision>
            <origin rpy="0 0 0" xyz="0 0 0" />
            <geometry>
                <mesh filename="package://agv_cobot/meshes/agv_cobot_5_link.STL" />
            </geometry>
        </collision>
    </link>
    <joint name="agv_cobot_5_joint" type="revolute">
        <origin rpy="-1.5708 0 0" xyz="0 0.2178 -0.0135" />
        <parent link="agv_cobot_4_link" />
        <child link="agv_cobot_5_link" />
        <axis xyz="0 0 -1" />
        <limit effort="40" lower="-3.14" upper="3.14" velocity="5" />
    </joint>
    <link name="agv_cobot_6_link">
        
<inertial>
            <origin rpy="0 0 0" xyz="-1.2745E-05 0.084294 0.0033492" />
            <mass value="1.2251" />
            <inertia ixx="0.0062841" ixy="-3.5019E-07" ixz="1.141E-07" iyy="0.0014649" iyz="0.0012842" izz="0.0059858" />
        </inertial>

        <visual>
            <origin rpy="0 0 0" xyz="0 0 0" />
            <geometry>
                <mesh filename="package://agv_cobot/meshes/agv_cobot_6_link.STL" />
            </geometry>
            <material name="">
                <color rgba="0.59216 0.66667 0.68235 1" />
            </material>
        </visual>
        <collision>
            <origin rpy="0 0 0" xyz="0 0 0" />
            <geometry>
                <mesh filename="package://agv_cobot/meshes/agv_cobot_6_link.STL" />
            </geometry>
        </collision>
    </link>
    <joint name="agv_cobot_6_joint" type="revolute">
        <origin rpy="1.5708 0 0" xyz="0 -0.0118 0.1482" />
        <parent link="agv_cobot_5_link" />
        <child link="agv_cobot_6_link" />
        <axis xyz="0 0 -1" />
        <limit effort="40" lower="-3.14" upper="3.14" velocity="5" />
    </joint>
    <link name="agv_cobot_7_link">
        
<inertial>
            <origin rpy="0 0 0" xyz="-4.7405E-05 -0.023063 0.012243" />
            <mass value="0.54274" />
            <inertia ixx="0.0011664" ixy="-2.239E-07" ixz="4.2105E-07" iyy="0.00063841" iyz="-0.00028236" izz="0.00095196" />
        </inertial>

        <visual>
            <origin rpy="0 0 0" xyz="0 0 0" />
            <geometry>
                <mesh filename="package://agv_cobot/meshes/agv_cobot_7_link.STL" />
            </geometry>
            <material name="">
                <color rgba="0.59216 0.66667 0.68235 1" />
            </material>
        </visual>
        <collision>
            <origin rpy="0 0 0" xyz="0 0 0" />
            <geometry>
                <mesh filename="package://agv_cobot/meshes/agv_cobot_7_link.STL" />
            </geometry>
        </collision>
    </link>
    <joint name="agv_cobot_7_base" type="revolute">
        <origin rpy="-1.5708 0 0" xyz="0 0.1933 -0.0118" />
        <parent link="agv_cobot_6_link" />
        <child link="agv_cobot_7_link" />
        <axis xyz="0 0 -1" />
        <limit effort="40" lower="-3.14" upper="3.14" velocity="5" />
    </joint>
    <link name="agv_grip_base">
        
<inertial>
            <origin rpy="0 0 0" xyz="0.061275 0.00045549 0.055237" />
            <mass value="0.2556" />
            <inertia ixx="0.00032252" ixy="-3.3909E-07" ixz="-4.8471E-07" iyy="0.00033384" iyz="2.7384E-08" izz="0.00023961" />
        </inertial>

        <visual>
            <origin rpy="0 0 0" xyz="0 0 0" />
            <geometry>
                <mesh filename="package://agv_cobot/meshes/agv_grip_base.STL" />
            </geometry>
            <material name="">
                <color rgba="0.79216 0.81961 0.93333 1" />
            </material>
        </visual>
        <collision>
            <origin rpy="0 0 0" xyz="0 0 0" />
            <geometry>
                <mesh filename="package://agv_cobot/meshes/agv_grip_base.STL" />
            </geometry>
        </collision>
    </link>
    <joint name="agv_grip_connection_joint" type="fixed">
        <origin rpy="0 3.14 -1.57" xyz="0 0 0.0571" />
        <parent link="agv_cobot_7_link" />
        <child link="agv_grip_base" />
        <axis xyz="0 0 0" />
        <limit effort="1" lower="-3.14" upper="3.14" velocity="5" />
    </joint>
    <material name="realSense_aluminum">
        <color rgba="0.5 0.5 0.5 1" />
    </material>
    <!-- camera body, with origin at bottom screw mount -->
    <joint name="realSense_joint" type="fixed">
        <origin rpy="0 1.5707 0" xyz="0.15455 0 0.139" />
        <parent link="agv_grip_base" />
        <child link="realSense_bottom_screw_frame" />
    </joint>
    <link name="realSense_bottom_screw_frame" />
    <joint name="realSense_link_joint" type="fixed">
        <origin rpy="0 0 0" xyz="0 0.0175 0.0125" />
        <parent link="realSense_bottom_screw_frame" />
        <child link="realSense_link" />
    </joint>
    <link name="realSense_link">
        <visual>
            <origin rpy="1.57079632679 0 1.57079632679" xyz="0.0149 -0.0175 0" />
            <geometry>
                <mesh filename="package://realsense2_description/meshes/d435.dae" />
            </geometry>
            <material name="realSense_aluminum" />
        </visual>
        <collision>
            <origin rpy="0 0 0" xyz="0 -0.0175 0" />
            <geometry>
                <box size="0.02505 0.09 0.025" />
            </geometry>
        </collision>
        
<inertial>
            <!-- The following are not reliable values, and should not be used for modeling -->
            <mass value="0.564" />
            <origin xyz="0 0 0" />
            <inertia ixx="0.003881243" ixy="0.0" ixz="0.0" iyy="0.000498940" iyz="0.0" izz="0.003879257" />
        </inertial>

    </link>
    <!-- camera depth joints and links -->
    <joint name="realSense_depth_joint" type="fixed">
        <origin rpy="0 0 0" xyz="0 0 0" />
        <parent link="realSense_link" />
        <child link="realSense_depth_frame" />
    </joint>
    <link name="realSense_depth_frame" />
    <joint name="realSense_depth_optical_joint" type="fixed">
        <origin rpy="-1.57079632679 0 -1.57079632679" xyz="0 0 0" />
        <parent link="realSense_depth_frame" />
        <child link="realSense_depth_optical_frame" />
    </joint>
    <link name="realSense_depth_optical_frame" />
    <!-- camera left IR joints and links -->
    <joint name="realSense_left_ir_joint" type="fixed">
        <origin rpy="0 0 0" xyz="0 0.0 0" />
        <parent link="realSense_depth_frame" />
        <child link="realSense_left_ir_frame" />
    </joint>
    <link name="realSense_left_ir_frame" />
    <joint name="realSense_left_ir_optical_joint" type="fixed">
        <origin rpy="-1.57079632679 0 -1.57079632679" xyz="0 0 0" />
        <parent link="realSense_left_ir_frame" />
        <child link="realSense_left_ir_optical_frame" />
    </joint>
    <link name="realSense_left_ir_optical_frame" />
    <!-- camera right IR joints and links -->
    <joint name="realSense_right_ir_joint" type="fixed">
        <origin rpy="0 0 0" xyz="0 0.0 0" />
        <parent link="realSense_depth_frame" />
        <child link="realSense_right_ir_frame" />
    </joint>
    <link name="realSense_right_ir_frame" />
    <joint name="realSense_right_ir_optical_joint" type="fixed">
        <origin rpy="-1.57079632679 0 -1.57079632679" xyz="0 0 0" />
        <parent link="realSense_right_ir_frame" />
        <child link="realSense_right_ir_optical_frame" />
    </joint>
    <link name="realSense_right_ir_optical_frame" />
    <!-- camera color joints and links -->
    <joint name="realSense_color_joint" type="fixed">
        <origin rpy="0 0 0" xyz="0 0.0 0" />
        <parent link="realSense_depth_frame" />
        <child link="realSense_color_frame" />
    </joint>
    <link name="realSense_color_frame" />
    <joint name="realSense_color_optical_joint" type="fixed">
        <origin rpy="-1.57079632679 0 -1.57079632679" xyz="0 0 0" />
        <parent link="realSense_color_frame" />
        <child link="realsense_camera_link" />
    </joint>
    <link name="realsense_camera_link" />
    <gazebo reference="realSense_link">
        <self_collide>0</self_collide>
        <enable_wind>0</enable_wind>
        <kinematic>0</kinematic>
        <gravity>1</gravity>
        <!--<mu>1</mu>-->
        <mu2>1</mu2>
        <fdir1>0 0 0</fdir1>
        <!--<slip1>0</slip1>
      <slip2>0</slip2>-->
        <kp>1e+13</kp>
        <kd>1</kd>
        <!--<max_vel>0.01</max_vel>
      <min_depth>0</min_depth>-->
        <sensor name="realSense_cobotcolor" type="camera">
            <camera name="realSense_cobot">
                <horizontal_fov>0.7508</horizontal_fov>
                <image>
                    <width>640</width>
                    <height>480</height>
                    <format>RGB_INT8</format>
                </image>
                <clip>
                    <near>0.1</near>
                    <far>100</far>
                </clip>
                <noise>
                    <type>gaussian</type>
                    <mean>0.0</mean>
                    <stddev>0.007</stddev>
                </noise>
            </camera>
            <always_on>1</always_on>
            <update_rate>30</update_rate>
            <visualize>0</visualize>
        </sensor>
        <sensor name="realSense_cobotired1" type="camera">
            <camera name="realSense_cobot">
                <horizontal_fov>0.7508</horizontal_fov>
                <image>
                    <width>640</width>
                    <height>480</height>
                    <format>L_INT8</format>
                </image>
                <clip>
                    <near>0.1</near>
                    <far>100</far>
                </clip>
                <noise>
                    <type>gaussian</type>
                    <mean>0.0</mean>
                    <stddev>0.05</stddev>
                </noise>
            </camera>
            <always_on>1</always_on>
            <update_rate>30</update_rate>
            <visualize>0</visualize>
        </sensor>
        <sensor name="realSense_cobotired2" type="camera">
            <camera name="realSense_cobot">
                <horizontal_fov>0.7508</horizontal_fov>
                <image>
                    <width>640</width>
                    <height>480</height>
                    <format>L_INT8</format>
                </image>
                <clip>
                    <near>0.1</near>
                    <far>100</far>
                </clip>
                <noise>
                    <type>gaussian</type>
                    <mean>0.0</mean>
                    <stddev>0.05</stddev>
                </noise>
            </camera>
            <always_on>1</always_on>
            <update_rate>30</update_rate>
            <visualize>0</visualize>
        </sensor>
        <sensor name="realSense_cobotdepth" type="depth">
            <camera name="realSense_cobot">
                <horizontal_fov>0.7508</horizontal_fov>
                <image>
                    <width>640</width>
                    <height>480</height>
                </image>
                <clip>
                    <near>0.1</near>
                    <far>100</far>
                </clip>
                <noise>
                    <type>gaussian</type>
                    <mean>0.0</mean>
                    <stddev>0.100</stddev>
                </noise>
            </camera>
            <always_on>1</always_on>
            <update_rate>30</update_rate>
            <visualize>0</visualize>
        </sensor>
    </gazebo>
    <gazebo>
        <plugin filename="librealsense_gazebo_plugin.so" name="realsense_cobot">
            <prefix>realSense_cobot</prefix>
            <depthUpdateRate>30.0</depthUpdateRate>
            <colorUpdateRate>30.0</colorUpdateRate>
            <infraredUpdateRate>30.0</infraredUpdateRate>
            <depthTopicName>depth/image_raw</depthTopicName>
            <depthCameraInfoTopicName>depth/camera_info</depthCameraInfoTopicName>
            <colorTopicName>color/image_raw</colorTopicName>
            <colorCameraInfoTopicName>color/camera_info</colorCameraInfoTopicName>
            <!-- <infrared1TopicName>infra1/image_raw</infrared1TopicName>
      	<infrared1CameraInfoTopicName>infra1/camera_info</infrared1CameraInfoTopicName>
      	<infrared2TopicName>infra2/image_raw</infrared2TopicName>
      	<infrared2CameraInfoTopicName>infra2/camera_info</infrared2CameraInfoTopicName> -->
            <colorOpticalframeName>realsense_cobot_camera_link</colorOpticalframeName>
            <depthOpticalframeName>realsense_cobot_camera_link</depthOpticalframeName>

            <rangeMinDepth>0.2</rangeMinDepth>
            <rangeMaxDepth>10.0</rangeMaxDepth>
            <pointCloud>true</pointCloud>
            <pointCloudTopicName>depth/points</pointCloudTopicName>
            <pointCloudCutoff>0.2</pointCloudCutoff>
        </plugin>
    </gazebo>
    <link name="agv_leftgrip">
        
<inertial>
            <origin rpy="0 0 0" xyz="-0.044287 7.8328E-08 0.080592" />
            <mass value="0.091742" />
            <inertia ixx="0.00012343" ixy="-2.2005E-13" ixz="-1.6329E-07" iyy="9.1345E-05" iyz="-1.62E-10" izz="3.4344E-05" />
        </inertial>

        <visual>
            <origin rpy="0 0 0" xyz="0 0 0" />
            <geometry>
                <mesh filename="package://agv_cobot/meshes/agv_leftgrip.STL" />
            </geometry>
            <material name="">
                <color rgba="0.79216 0.81961 0.93333 1" />
            </material>
        </visual>
        <collision>
            <origin rpy="0 0 0" xyz="0 0 0" />
            <geometry>
                <mesh filename="package://agv_cobot/meshes/agv_leftgrip.STL" />
            </geometry>
        </collision>
    </link>
    <joint name="agv_leftgrip_joint" type="prismatic">
        <origin rpy="3.14 0 1.5707" xyz="0.07915 0 0.0094" />
        <parent link="agv_grip_base" />
        <child link="agv_leftgrip" />
        <axis xyz="1 0 0" />
        <limit effort="10" lower="-0.025" upper="0.060" velocity="5" />
    </joint>
    <link name="agv_rightgrip">
        
<inertial>
            <origin rpy="0 0 0" xyz="0.044287 -7.8328E-08 0.080592" />
            <mass value="0.091742" />
            <inertia ixx="0.00012343" ixy="-2.2005E-13" ixz="1.6329E-07" iyy="9.1345E-05" iyz="1.62E-10" izz="3.4344E-05" />
        </inertial>

        <visual>
            <origin rpy="0 0 0" xyz="0 0 0" />
            <geometry>
                <mesh filename="package://agv_cobot/meshes/agv_rightgrip.STL" />
            </geometry>
            <material name="">
                <color rgba="0.79216 0.81961 0.93333 1" />
            </material>
        </visual>
        <collision>
            <origin rpy="0 0 0" xyz="0 0 0" />
            <geometry>
                <mesh filename="package://agv_cobot/meshes/agv_rightgrip.STL" />
            </geometry>
        </collision>
    </link>
    <joint name="agv_rightgrip_joint" type="prismatic">
        <origin rpy="3.14 0 1.5707" xyz="0.07915 0 0.0094" />
        <parent link="agv_grip_base" />
        <child link="agv_rightgrip" />
        <axis xyz="-1 0 0" />
        <limit effort="10" lower="-0.025" upper="0.060" velocity="5" />
    </joint>
    <gazebo reference="agv_leftgrip">
        <kp>1000000.0</kp>
        <kd>1.0</kd>
        <mu1>100.0</mu1>
        <mu2>100.0</mu2>
        <minDepth>0.003</minDepth>
    </gazebo>
    <gazebo reference="agv_rightgrip">
        <kp>1000000.0</kp>
        <kd>1.0</kd>
        <mu1>100.0</mu1>
        <mu2>100.0</mu2>
        <minDepth>0.003</minDepth>
    </gazebo>

	<!--<gazebo>
	   <plugin name="gazebo_grasp_fix" filename="libgazebo_grasp_fix.so">
		    <arm>
		       <arm_name>grasping</arm_name>
		       <palm_link> agv_rightgrip  </palm_link>
		       <gripper_link> agv_leftgrip </gripper_link>
		    </arm>
		   <forces_angle_tolerance>100</forces_angle_tolerance>
		   <update_rate>10</update_rate>
		   <grip_count_threshold>1</grip_count_threshold>
		   <max_grip_count>1</max_grip_count>
		   <release_tolerance>0.005</release_tolerance>
		   <disable_collisions_on_attach>false</disable_collisions_on_attach>
		   <contact_topic>__default_topic__</contact_topic>
		</plugin>
	</gazebo>-->

    <gazebo>
        <gripper name="grasping">
            <grasp_check>
                <attach_steps>1</attach_steps>
                <detach_steps>1</detach_steps>
                <min_contact_count>1</min_contact_count>
            </grasp_check>
            <gripper_link>agv_leftgrip</gripper_link>
            <palm_link>agv_rightgrip</palm_link>
        </gripper>
    </gazebo>

    <joint name="base_fixed" type="fixed">
        <parent link="base_link" />
        <child link="agv_cobot_base" />
        <origin rpy="0 0 0" xyz="-0.21547 -0.0010007 0.3" />
    </joint>
    
<transmission name="trans_agv_leftwheel_joint">
        <type>transmission_interface/SimpleTransmission</type>
        <joint name="agv_leftwheel_joint">
            <hardwareInterface>hardware_interface/PositionJointInterface</hardwareInterface>
        </joint>
        <actuator name="agv_leftwheel_joint_motor">
            <hardwareInterface>hardware_interface/PositionJointInterface</hardwareInterface>
            <mechanicalReduction>1</mechanicalReduction>
        </actuator>
    </transmission>
    <transmission name="trans_agv_rightwheel_joint">
        <type>transmission_interface/SimpleTransmission</type>
        <joint name="agv_rightwheel_joint">
            <hardwareInterface>hardware_interface/PositionJointInterface</hardwareInterface>
        </joint>
        <actuator name="agv_rightwheel_joint_motor">
            <hardwareInterface>hardware_interface/PositionJointInterface</hardwareInterface>
            <mechanicalReduction>1</mechanicalReduction>
        </actuator>
    </transmission>
    <transmission name="trans_agv_casterwheel_11_joint">
        <type>transmission_interface/SimpleTransmission</type>
        <joint name="agv_casterwheel_11_joint">
            <hardwareInterface>hardware_interface/PositionJointInterface</hardwareInterface>
        </joint>
        <actuator name="agv_casterwheel_11_joint_motor">
            <hardwareInterface>hardware_interface/PositionJointInterface</hardwareInterface>
            <mechanicalReduction>1</mechanicalReduction>
        </actuator>
    </transmission>
    <transmission name="trans_agv_casterwheel_12_joint">
        <type>transmission_interface/SimpleTransmission</type>
        <joint name="agv_casterwheel_12_joint">
            <hardwareInterface>hardware_interface/PositionJointInterface</hardwareInterface>
        </joint>
        <actuator name="agv_casterwheel_12_joint_motor">
            <hardwareInterface>hardware_interface/PositionJointInterface</hardwareInterface>
            <mechanicalReduction>1</mechanicalReduction>
        </actuator>
    </transmission>
    <transmission name="trans_agv_casterwheel_21_joint">
        <type>transmission_interface/SimpleTransmission</type>
        <joint name="agv_casterwheel_21_joint">
            <hardwareInterface>hardware_interface/PositionJointInterface</hardwareInterface>
        </joint>
        <actuator name="agv_casterwheel_21_joint_motor">
            <hardwareInterface>hardware_interface/PositionJointInterface</hardwareInterface>
            <mechanicalReduction>1</mechanicalReduction>
        </actuator>
    </transmission>
    <transmission name="trans_agv_casterwheel_22_joint">
        <type>transmission_interface/SimpleTransmission</type>
        <joint name="agv_casterwheel_22_joint">
            <hardwareInterface>hardware_interface/PositionJointInterface</hardwareInterface>
        </joint>
        <actuator name="agv_casterwheel_22_joint_motor">
            <hardwareInterface>hardware_interface/PositionJointInterface</hardwareInterface>
            <mechanicalReduction>1</mechanicalReduction>
        </actuator>
    </transmission>
    <transmission name="trans_agv_casterwheel_31_joint">
        <type>transmission_interface/SimpleTransmission</type>
        <joint name="agv_casterwheel_31_joint">
            <hardwareInterface>hardware_interface/PositionJointInterface</hardwareInterface>
        </joint>
        <actuator name="agv_casterwheel_31_joint_motor">
            <hardwareInterface>hardware_interface/PositionJointInterface</hardwareInterface>
            <mechanicalReduction>1</mechanicalReduction>
        </actuator>
    </transmission>
    <transmission name="trans_agv_casterwheel_32_joint">
        <type>transmission_interface/SimpleTransmission</type>
        <joint name="agv_casterwheel_32_joint">
            <hardwareInterface>hardware_interface/PositionJointInterface</hardwareInterface>
        </joint>
        <actuator name="agv_casterwheel_32_joint_motor">
            <hardwareInterface>hardware_interface/PositionJointInterface</hardwareInterface>
            <mechanicalReduction>1</mechanicalReduction>
        </actuator>
    </transmission>
    <transmission name="trans_agv_casterwheel_41_joint">
        <type>transmission_interface/SimpleTransmission</type>
        <joint name="agv_casterwheel_41_joint">
            <hardwareInterface>hardware_interface/PositionJointInterface</hardwareInterface>
        </joint>
        <actuator name="agv_casterwheel_41_joint_motor">
            <hardwareInterface>hardware_interface/PositionJointInterface</hardwareInterface>
            <mechanicalReduction>1</mechanicalReduction>
        </actuator>
    </transmission>
    <transmission name="trans_agv_casterwheel_42">
        <type>transmission_interface/SimpleTransmission</type>
        <joint name="agv_casterwheel_42">
            <hardwareInterface>hardware_interface/PositionJointInterface</hardwareInterface>
        </joint>
        <actuator name="agv_casterwheel_42_motor">
            <hardwareInterface>hardware_interface/PositionJointInterface</hardwareInterface>
            <mechanicalReduction>1</mechanicalReduction>
        </actuator>
    </transmission>
    <transmission name="trans_agv_cobot_1_joint">
        <type>transmission_interface/SimpleTransmission</type>
        <joint name="agv_cobot_1_joint">
            <hardwareInterface>hardware_interface/PositionJointInterface</hardwareInterface>
        </joint>
        <actuator name="agv_cobot_1_joint_motor">
            <hardwareInterface>hardware_interface/PositionJointInterface</hardwareInterface>
            <mechanicalReduction>1</mechanicalReduction>
        </actuator>
    </transmission>
    <transmission name="trans_agv_cobot_2_joint">
        <type>transmission_interface/SimpleTransmission</type>
        <joint name="agv_cobot_2_joint">
            <hardwareInterface>hardware_interface/PositionJointInterface</hardwareInterface>
        </joint>
        <actuator name="agv_cobot_2_joint_motor">
            <hardwareInterface>hardware_interface/PositionJointInterface</hardwareInterface>
            <mechanicalReduction>1</mechanicalReduction>
        </actuator>
    </transmission>
    <transmission name="trans_agv_cobot_3_joint">
        <type>transmission_interface/SimpleTransmission</type>
        <joint name="agv_cobot_3_joint">
            <hardwareInterface>hardware_interface/PositionJointInterface</hardwareInterface>
        </joint>
        <actuator name="agv_cobot_3_joint_motor">
            <hardwareInterface>hardware_interface/PositionJointInterface</hardwareInterface>
            <mechanicalReduction>1</mechanicalReduction>
        </actuator>
    </transmission>
    <transmission name="trans_agv_cobot_4_joint">
        <type>transmission_interface/SimpleTransmission</type>
        <joint name="agv_cobot_4_joint">
            <hardwareInterface>hardware_interface/PositionJointInterface</hardwareInterface>
        </joint>
        <actuator name="agv_cobot_4_joint_motor">
            <hardwareInterface>hardware_interface/PositionJointInterface</hardwareInterface>
            <mechanicalReduction>1</mechanicalReduction>
        </actuator>
    </transmission>
    <transmission name="trans_agv_cobot_5_joint">
        <type>transmission_interface/SimpleTransmission</type>
        <joint name="agv_cobot_5_joint">
            <hardwareInterface>hardware_interface/PositionJointInterface</hardwareInterface>
        </joint>
        <actuator name="agv_cobot_5_joint_motor">
            <hardwareInterface>hardware_interface/PositionJointInterface</hardwareInterface>
            <mechanicalReduction>1</mechanicalReduction>
        </actuator>
    </transmission>
    <transmission name="trans_agv_cobot_6_joint">
        <type>transmission_interface/SimpleTransmission</type>
        <joint name="agv_cobot_6_joint">
            <hardwareInterface>hardware_interface/PositionJointInterface</hardwareInterface>
        </joint>
        <actuator name="agv_cobot_6_joint_motor">
            <hardwareInterface>hardware_interface/PositionJointInterface</hardwareInterface>
            <mechanicalReduction>1</mechanicalReduction>
        </actuator>
    </transmission>
    <transmission name="trans_agv_cobot_7_base">
        <type>transmission_interface/SimpleTransmission</type>
        <joint name="agv_cobot_7_base">
            <hardwareInterface>hardware_interface/PositionJointInterface</hardwareInterface>
        </joint>
        <actuator name="agv_cobot_7_base_motor">
            <hardwareInterface>hardware_interface/PositionJointInterface</hardwareInterface>
            <mechanicalReduction>1</mechanicalReduction>
        </actuator>
    </transmission>
    <transmission name="trans_agv_leftgrip_joint">
        <type>transmission_interface/SimpleTransmission</type>
        <joint name="agv_leftgrip_joint">
            <hardwareInterface>hardware_interface/PositionJointInterface</hardwareInterface>
        </joint>
        <actuator name="agv_leftgrip_joint_motor">
            <hardwareInterface>hardware_interface/PositionJointInterface</hardwareInterface>
            <mechanicalReduction>1</mechanicalReduction>
        </actuator>
    </transmission>
    <transmission name="trans_agv_rightgrip_joint">
        <type>transmission_interface/SimpleTransmission</type>
        <joint name="agv_rightgrip_joint">
            <hardwareInterface>hardware_interface/PositionJointInterface</hardwareInterface>
        </joint>
        <actuator name="agv_rightgrip_joint_motor">
            <hardwareInterface>hardware_interface/PositionJointInterface</hardwareInterface>
            <mechanicalReduction>1</mechanicalReduction>
        </actuator>
    </transmission>
    <gazebo>
        <plugin name="gazebo_ros_control" filename="libgazebo_ros_control.so">
            <robotNamespace>/</robotNamespace>
        </plugin>
    </gazebo>
</robot>
